<?xml version="1.0"?>
<robot name="gball" xmlns:xacro="http://www.ros.org/wiki/xacro"> 

  <!-- Import all Gazebo-customization elements, including Gazebo colors -->
  <xacro:include filename="$(find guardian_description)/urdf/v7/guardian.gazebo" />


  <!-- Robot mechanical and motor parameters -->
  <xacro:property name="PI" value="3.1415926535897931"/>
  <xacro:property name="wheel_offset_x" value="0.300" />    <!-- x,y,z in base_footprint CS -->
  <xacro:property name="wheel_offset_y" value="0.265" /> 
  <xacro:property name="wheel_offset_z" value="0.0" /> 
  <xacro:property name="wheel_joint_damping" value="0.0" />
  <xacro:property name="wheel_joint_friction" value="0.0" />

  <xacro:property name="wheel_joint_effort_limit" value="200.0" />
  <xacro:property name="wheel_joint_velocity_limit" value="200.0" />
  <xacro:property name="wheel_mechanical_reduction" value="1.0" />

  <xacro:property name="ptz_joint_effort_limit" value="100.0" /> 
  <xacro:property name="ptz_joint_velocity_limit" value="100.0"/>  
  <xacro:property name="ptz_joint_friction" value="0.1" />
  <xacro:property name="ptz_joint_damping" value="0.1" />
  <xacro:property name="ptz_mechanical_reduction" value="1.0" />

  
  <!-- Used for fixing robot to Gazebo 'base_link' -->
  <!-- link name="world"/>
  <joint name="fwf" type="planar">
    <parent link="world"/>
    <child link="base_footprint"/>
  </joint -->

  <!-- BASE FOOTPRINT -->
  <!-- base_footprint is a fictitious link(frame) that is on the ground right below base_link origin,
             navigation stack depends on this frame -->
  <link name="base_footprint">
      <visual>
          <origin xyz="0 0 0" rpy="0 0 0" />
          <geometry>
             <box size="0.001 0.001 0.001" />
          </geometry>
      </visual>

      <collision>
          <origin xyz="0 0 0" rpy="0 0 0" />
          <geometry>
            <box size="0.001 0.001 0.001" />
         </geometry>
     </collision>
  </link>

  <joint name="base_footprint_joint" type="fixed">
     <!--NB: While you would think this would make it go up, it is oddly reversed.
      This moves the joint to 0,0,0 where we want it for rviz, etc. -->
     <!-- origin xyz="0 0 0.130" rpy="0 0 0" / -->
     <origin xyz="0 0 0.18" rpy="0 0 0" />
     <parent link="base_footprint"/>
     <child link="base_link" />
  </joint>


  <!-- BASE_LINK (RED) -->
  <link name="base_link">
    <inertial>
      <mass value="95.0" />
      <origin xyz="0 0 0" />
      <inertia  ixx="3.737" ixy="0.008"  ixz="-0.144"  iyy="8.311"  iyz="-0.004"  izz="8.893" />
    </inertial>
    <visual>
       <origin xyz="0 0 0" rpy="0 0 0" />
       <geometry>
	 <mesh filename="package://guardian_description/meshes/chassis/v7/chassisV7.dae"/>
       </geometry>
    </visual>
    <collision>
       <origin xyz="0 0 0" rpy="0 0 0 " />
       <geometry>
         <mesh filename="package://guardian_description/meshes/chassis/v7/chassisV7.dae"/>
       </geometry>
    </collision>     
  </link>


  <!-- LEFT TRACK (BLACK) -->
  <link name="left_track">
    <inertial>
      <mass value="1.250" />
      <origin xyz="0 0 0" /> 
      <inertia  ixx="0.0109375" ixy="0.0"  ixz="0.0"  iyy="0.021125"  iyz="0.0"  izz="0.0109375" />
    </inertial>
    <visual>
        <origin xyz="0 0 0" rpy="0 0 0" /> 
        <geometry>
	 <mesh filename="package://guardian_description/meshes/others/v5/trackV5_l.dae"/>
        </geometry>
	<material name="black">
  		<color rgba="0.1 0.1 0.1 1"/>
      	</material>
    </visual>
    <collision>
       <origin xyz="0 0 0" rpy="0 0 0" />
       <geometry>
         <mesh filename="package://guardian_description/meshes/others/v5/trackV5_l.dae"/>
       </geometry>
    </collision>
  </link>
  

  <joint name="joint_left_track" type="fixed">
    <parent link="base_link"/>
    <child link="left_track"/>
    <origin xyz="0.0 0.0 0.0" rpy="0 0 0" /> 
  </joint>


  <!-- RIGHT TRACK (BLACK) -->
  <link name="right_track">
    <inertial>
      <mass value="1.250" />
      <origin xyz="0 0 0" /> 
      <inertia  ixx="0.0109375" ixy="0.0"  ixz="0.0"  iyy="0.021125"  iyz="0.0"  izz="0.0109375" />
    </inertial>
    <visual>
       <origin xyz="0 0 0" rpy="0 0 0" /> 
       <geometry>
	 	 <mesh filename="package://guardian_description/meshes/others/v5/trackV5_l.dae"/>
       </geometry>
	   <material name="black">
		 <color rgba="0.1 0.1 0.1 1"/>
       </material>
    </visual>
    <collision>
       <origin xyz="0 0 0" rpy="0 0 0" />
       <geometry>
         <mesh filename="package://guardian_description/meshes/others/v5/trackV5_l.dae"/>
       </geometry>
    </collision>
  </link>
  

  <joint name="joint_right_track" type="fixed">
    <parent link="base_link"/>
    <child link="right_track"/>
    <origin xyz="0.0 0.0 0.0" rpy="0 0 3.1415926535" /> 
  </joint>

  <!-- BACK LEFT WHEEL (GREY) -->
  <link name="back_left_wheel">
    <inertial>
      <mass value="4.5" />
      <origin xyz="0 0 0" rpy="0 0 3.1416"/> 
      <inertia  ixx="0.059" ixy="0.0"  ixz="0.0"  iyy="0.055"  iyz="0.0"  izz="0.059" />
    </inertial>
    <visual>
       <origin xyz="0 0 0" rpy="0 0 3.1416" /> 
       <geometry>
	 	 <mesh filename="package://guardian_description/meshes/wheel.dae"/>
       </geometry>
	   <material name="grey">
		 <color rgba="0.3 0.3 0.3 1"/>
       </material>
    </visual>
    <collision>
       <origin xyz="0 0 0" rpy="0 0 3.1416" />
       <geometry>
         <mesh filename="package://guardian_description/meshes/wheel.dae"/>
       </geometry>
    </collision>
  </link>

  <joint name="joint_back_left_wheel" type="continuous">
    <parent link="base_link"/>
    <child link="back_left_wheel"/>
    <origin xyz="-${wheel_offset_x} ${wheel_offset_y} 0" rpy="0 0 0" /> 
    <axis xyz="0 1 0" rpy="0 0 0" />
    <limit effort="${wheel_joint_effort_limit}" velocity="${wheel_joint_velocity_limit}"/>
    <joint_properties damping="${wheel_joint_damping}" friction="{wheel_joint_friction}"/>
  </joint>

  <transmission name="joint_blw_trans">
	 <type>transmission_interface/SimpleTransmission</type>
     <joint name="joint_back_left_wheel" />
     <actuator name="joint_blw_motor">
	    <hardwareInterface>EffortJointInterface</hardwareInterface>
		<!-- hardwareInterface>VelocityJointInterface</hardwareInterface -->
        <mechanicalReduction>${wheel_mechanical_reduction}</mechanicalReduction>
     	<!-- motorTorqueConstant>1</motorTorqueConstant -->
     </actuator>
  </transmission>

  <!-- BACK RIGHT WHEEL (BLACK) -->
  <link name="back_right_wheel">
    <inertial>
      <mass value="4.5" />
      <origin xyz="0 0 0" rpy="0 0 0"/>
      <inertia  ixx="0.059" ixy="0.0"  ixz="0.0"  iyy="0.055"  iyz="0.0"  izz="0.059" />
    </inertial>

    <visual>
       <origin xyz="0 0 0" rpy="0 0 0" /> 
       <geometry>
         <mesh filename="package://guardian_description/meshes/wheel.dae"/>
       </geometry>
	   <material name="gray">
		 <color rgba="0.3 0.3 0.3 1"/>
       </material>
    </visual>
    <collision>
       <origin xyz="0 0 0" rpy="0 0 0" /> 
       <geometry>
         <mesh filename="package://guardian_description/meshes/wheel.dae"/>
       </geometry>
    </collision>
  </link>

  <joint name="joint_back_right_wheel" type="continuous">
    <parent link="base_link"/>
    <child link="back_right_wheel"/>
    <origin xyz="-${wheel_offset_x} -${wheel_offset_y} 0" rpy="0 0 0" /> 
    <axis xyz="0 1 0" rpy="0 0 0" />
    <limit effort="${wheel_joint_effort_limit}" velocity="${wheel_joint_velocity_limit}"/>
    <joint_properties damping="${wheel_joint_damping}" friction="{wheel_joint_friction}"/>
  </joint>

  <transmission name="joint_brw_trans">
    <type>transmission_interface/SimpleTransmission</type>
    <joint name="joint_back_right_wheel" />
    <actuator name="joint_brw_motor">
	   <hardwareInterface>EffortJointInterface</hardwareInterface>
       <!-- hardwareInterface>VelocityJointInterface</hardwareInterface -->
       <mechanicalReduction>${wheel_mechanical_reduction}</mechanicalReduction>
	   <!-- motorTorqueConstant>1</motorTorqueConstant -->
    </actuator>
  </transmission>

  <!-- FRONT LEFT WHEEL (GREY) -->
  <link name="front_left_wheel">
    <inertial>
      <mass value="4.5" />
      <origin xyz="0 0 0" rpy="0 0 3.1416"/>
      <inertia  ixx="0.059" ixy="0.0"  ixz="0.0"  iyy="0.055"  iyz="0.0"  izz="0.059" />
    </inertial>
    
    <visual>
       <origin xyz="0 0 0" rpy="0 0 3.1416" /> 
       <geometry>
         <mesh filename="package://guardian_description/meshes/wheel.dae"/>
       </geometry>
	   <material name="grey">
		 <color rgba="0.3 0.3 0.3 1"/>
       </material>
    </visual>
    <collision>
       <origin xyz="0 0 0" rpy="0 0 3.1416" /> 
       <geometry>
         <mesh filename="package://guardian_description/meshes/wheel.dae"/>
       </geometry>
    </collision>
  </link>

  <joint name="joint_front_left_wheel" type="continuous">
    <parent link="base_link"/>
    <child link="front_left_wheel"/>
    <origin xyz="${wheel_offset_x} ${wheel_offset_y} 0" rpy="0 0 0" /> 
    <axis xyz="0 1 0" rpy="0 0 0" />
    <limit effort="${wheel_joint_effort_limit}" velocity="${wheel_joint_velocity_limit}"/>
    <joint_properties damping="${wheel_joint_damping}" friction="{wheel_joint_friction}"/>
  </joint>

  <transmission name="joint_flw_trans">
	 <type>transmission_interface/SimpleTransmission</type>
     <joint name="joint_front_left_wheel" />
     <actuator name="joint_flw_motor">
	   <hardwareInterface>EffortJointInterface</hardwareInterface>
       <!-- hardwareInterface>VelocityJointInterface</hardwareInterface -->
       <mechanicalReduction>${wheel_mechanical_reduction}</mechanicalReduction>
       <!-- motorTorqueConstant>1</motorTorqueConstant -->
     </actuator>     
  </transmission>


  <!-- FRONT RIGHT WHEEL (GREY) -->
  <link name="front_right_wheel">
    <inertial>
      <mass value="4.5" />
      <origin xyz="0 0 0" rpy="0 0 0"/>
      <inertia  ixx="0.059" ixy="0.0"  ixz="0.0"  iyy="0.055"  iyz="0.0"  izz="0.059" />
    </inertial>

    <visual>
       <origin xyz="0 0 0" rpy="0 0 0" /> 
       <geometry>
         <mesh filename="package://guardian_description/meshes/wheel.dae"/>
       </geometry>
	   <material name="grey">
		 <color rgba="0.3 0.3 0.3 1"/>
       </material>
    </visual>
    <collision>
       <origin xyz="0 0 0" rpy="0 0 0" /> 
       <geometry>
         <mesh filename="package://guardian_description/meshes/wheel.dae"/> 
       </geometry>
    </collision>
  </link>

  <joint name="joint_front_right_wheel" type="continuous">
    <parent link="base_link"/>
    <child link="front_right_wheel"/>
    <origin xyz="${wheel_offset_x} -${wheel_offset_y} 0" rpy="0 0 0" /> 
    <axis xyz="0 1 0" rpy="0 0 0" />
    <limit effort="${wheel_joint_effort_limit}" velocity="${wheel_joint_velocity_limit}"/>
    <joint_properties damping="${wheel_joint_damping}" friction="{wheel_joint_friction}"/>
  </joint>


  <transmission name="joint_frw_trans">
	 <type>transmission_interface/SimpleTransmission</type>
     <joint name="joint_front_right_wheel" />
     <actuator name="joint_frw_motor">
	   <hardwareInterface>EffortJointInterface</hardwareInterface>
	   <!-- hardwareInterface>VelocityJointInterface</hardwareInterface -->    
       <mechanicalReduction>${wheel_mechanical_reduction}</mechanicalReduction>
       <!-- motorTorqueConstant>1</motorTorqueConstant -->
     </actuator>
     <!-- motorTorqueConstant>1</motorTorqueConstant -->
  </transmission>



  <!-- HOKUYO BACK SENSOR -->
  <joint name="hokuyo_back_laser_joint" type="fixed">
     <axis xyz="0 1 0" />
     <origin xyz="-0.43171 0 0.29163" rpy="0 0 ${PI}"/>
     <parent link="base_link"/>
     <child link="hokuyo_back_laser_link"/>
  </joint>
  <!-- Hokuyo Laser -->
  <link name="hokuyo_back_laser_link">
    <collision>
      <origin xyz="0 0 0" rpy="0 0 0"/>
      <geometry>
	<box size="0.1 0.1 0.1"/>
      </geometry>
    </collision>

    <!-- visual>
      <origin xyz="0 0 0" rpy="0 0 0"/>
      <geometry>
        <mesh filename="package://guardian_description/meshes/hokuyo-utm30-lx.dae"/>
      </geometry>
    </visual -->

    <inertial>
      <mass value="1e-5" />
      <origin xyz="0 0 0" rpy="0 0 0"/>
      <inertia ixx="1e-6" ixy="0" ixz="0" iyy="1e-6" iyz="0" izz="1e-6" />
    </inertial>
  </link>
  
  <joint name="laser_tilt_mount_joint" type="fixed">
     <axis xyz="0 1 0" />
     <origin xyz="0.46781 0 0.24299"/>
     <parent link="base_link"/>
     <child link="laser_tilt_mount_link"/>
     <limit effort="30" lower="-2.6" upper="2.6" velocity="2.0"/>
	 <dynamics damping="100"/>
  </joint>
  <link name="laser_tilt_mount_link"></link>

  <!--joint name="laser_tilt_mount_inverted_joint" type="fixed">
     <axis xyz="0 1 0" />
     <origin xyz="0 0 0" rpy="${PI} 0 0"/>
     <parent link="laser_tilt_mount_link"/>
     <child link="laser_tilt_mount_inverted_link"/>
     <limit effort="30" lower="-2.6" upper="2.6" velocity="2.0"/>
	 <dynamics damping="100"/>
  </joint>
  <link name="laser_tilt_mount_inverted_link">
    
  </link-->
  
  <!-- HOKUYO FRONTAL ROTATION -->
  <joint name="laser_tilt_joint" type="revolute">
     <axis xyz="0 1 0" />
     <origin xyz="0 0 0"/>
     <parent link="laser_tilt_mount_link"/>
     <child link="laser_tilt_link"/>
     <limit effort="30" lower="-2.6" upper="2.6" velocity="2.0"/>
	 <dynamics damping="100"/>
  </joint>
  <transmission name="hokuyo_frontal_laser_rotation_transmission" type="pr2_mechanism_model/SimpleTransmission">
	<actuator name="hokuyo_frontal_laser_rotation_joint_motor"/>
	<joint name="hokuyo_frontal_laser_rotation_joint"/>
	<mechanicalReduction>1</mechanicalReduction>
	<motorTorqueConstant>1</motorTorqueConstant>
  </transmission>	
  
  <link name="laser_tilt_link">
     <visual>
       <origin xyz="0 0 0" rpy="0 0 0" />
       <geometry>
	 <mesh filename="package://guardian_description/meshes/chassis/v7/hokuyo_tilt.dae"/>
       </geometry>
    </visual>
    <collision>
       <origin xyz="0 0 0" rpy="0 0 0 " />
       <geometry>
         <mesh filename="package://guardian_description/meshes/chassis/v7/hokuyo_tilt.dae"/>
       </geometry>
    </collision>  

    <inertial>
      <mass value="1e-5" />
      <origin xyz="0 0 0" rpy="0 0 0"/>
      <inertia ixx="1e-6" ixy="0" ixz="0" iyy="1e-6" iyz="0" izz="1e-6" />
    </inertial>
  </link>
  
  <!-- HOKUYO FRONTAL SENSOR -->
  <joint name="hokuyo_frontal_laser_joint" type="fixed">
     <axis xyz="0 1 0" />
     <origin xyz="0.066 0 0.0"/>
     <parent link="laser_tilt_link"/>
     <child link="hokuyo_frontal_laser_link"/>
  </joint>
  <!-- Hokuyo Laser -->
  <link name="hokuyo_frontal_laser_link">
    <collision>
      <origin xyz="0 0 0" rpy="0 0 0"/>
      <geometry>
	<box size="0.1 0.1 0.1"/>
      </geometry>
    </collision>

    <!-- visual>
      <origin xyz="0 0 0" rpy="0 0 0"/>
      <geometry>
        <mesh filename="package://guardian_description/meshes/hokuyo-utm30-lx.dae"/>
      </geometry>
    </visual -->

    <inertial>
      <mass value="1e-5" />
      <origin xyz="0 0 0" rpy="0 0 0"/>
      <inertia ixx="1e-6" ixy="0" ixz="0" iyy="1e-6" iyz="0" izz="1e-6" />
    </inertial>
  </link>

  <!-- IMU SENSOR -->
  <joint name="imu_joint" type="fixed">
      <axis xyz="1 0 0"/> <!-- 0 1 0 -->
      <origin xyz="0 0 0.2825"/>
      <parent link="base_link"/>
      <child link="imu_link"/>
  </joint>

  <link name="imu_link">
      <inertial>
        <mass value="0.001"/>
        <origin rpy="0 0 0" xyz="0 0 0"/>
        <inertia ixx="0.0001" ixy="0" ixz="0" iyy="0.000001" iyz="0" izz="0.0001"/>
      </inertial>
      <visual>
        <origin rpy="0 0 0" xyz="0 0 0"/>
        <geometry>
          <box size="0.001 0.001 0.001"/>
        </geometry>
      </visual>
      <collision>
        <origin rpy="0 0 0" xyz="0 0 0"/>
        <geometry>
          <box size=".001 .001 .001"/>
        </geometry>
      </collision>
  </link>


</robot>

